<?xml version="1.0"?>
<robot xmlns:xacro="http://www.ros.org/wiki/xacro" >
    <xacro:include filename="inertial_macros.xacro" />

    <material name="white">
        <color rgba="1 1 1 1" />
    </material>

    <material name="orange">
        <color rgba="1 0.3 0.1 1"/>
    </material>

    <material name="blue">
        <color rgba="0.2 0.2 1 1"/>
    </material>

    <material name="black">
        <color rgba="0 0 0 1"/>
    </material>

    <material name="red">
        <color rgba="1 0 0 1"/>
    </material>

    <!-- BASE LINK -->

    <link name="base_link">
    
    </link>
    <joint name="chassis_joint" type="fixed">
        <parent link="base_link"/>
        <child link="chassis"/>
        <origin xyz="-0.1 0 0"/>
    </joint>
    <link name="chassis">
    <visual>
        <origin xyz="0.15 0 0.075" rpy="0 0 ${pi/2}"/>
        <geometry>
            <mesh filename="file://$(find articubot_one)/description/Body1.dae" scale="0.01 0.01 0.01"/>
        </geometry>
        <material name="white"/>
    </visual>
    <collision>
        <origin xyz="0.15 0 0.075" rpy="0 0 ${pi/2}"/>
        <geometry>/home/swg/robot_ws/src/articubot_one/model/Body1.dae
            <mesh filename="file://$(find articubot_one)/description/Body1.dae" scale="0.01 0.01 0.01"/>
        </geometry>
    </collision>
    <xacro:inertial_box mass="100" x="0.3" y="0.3" z="0.15">
        <origin xyz="0.2 0 0.1" rpy="0 0 0"/>
    </xacro:inertial_box>
    </link>
    <gazebo reference="chassis">
    <material>Gazebo/Green</material>
    </gazebo>
    <!-- LEFT WHEEL -->

    <joint name="left_wheel_joint" type="continuous">
        <parent link="base_link"/>
        <child link="left_wheel"/>
        <origin xyz="0.2 0.175 0.05" rpy="-${pi/2} 0 0"/>
        <axis xyz="0 0 -1"/>
    </joint>
    <link name="left_wheel">
    <visual>
        <geometry>
            <cylinder length="0.04" radius="0.05" />
        </geometry>
        <material name="blue"/>
    </visual>
    <collision>
        <geometry>
            <cylinder length="0.04" radius="0.05" />
        </geometry>
    </collision>
    <xacro:inertial_cylinder mass="10" length="0.05" radius="0.05">
        <origin xyz="0 0 0" rpy="0 0 0"/>
    </xacro:inertial_cylinder>
    </link>

    <!-- RIGHT WHEEL -->

<joint name="right_wheel_joint" type="continuous">
    <parent link="base_link"/>
    <child link="right_wheel"/>
    <origin xyz="0.2 -0.175 0.05" rpy="${pi/2} 0 0"/>
    <axis xyz="0 0 1"/>
</joint>

<link name="right_wheel">
    <visual>
        <geometry>
            <cylinder length="0.04" radius="0.05" />
        </geometry>
        <material name="blue"/>
    </visual>
    
    <collision>
        <geometry>
            <cylinder length="0.04" radius="0.05" />
        </geometry>
    </collision>
    <xacro:inertial_cylinder mass="10" length="0.05" radius="0.05">
        <origin xyz="0 0 0" rpy="0 0 0"/>
    </xacro:inertial_cylinder>
</link>
<!-- R LEFT WHEEL -->

    <joint name="R_left_wheel_joint" type="continuous">
        <parent link="base_link"/>
        <child link="R_left_wheel"/>
        <origin xyz="-0.1 0.175 0.05" rpy="-${pi/2} 0 0"/>
        <axis xyz="0 0 -1"/>
    </joint>
    <link name="R_left_wheel">
    <visual>
        <geometry>
            <cylinder length="0.04" radius="0.05" />
        </geometry>
        <material name="blue"/>
    </visual>
    <collision>
        <geometry>
            <cylinder length="0.04" radius="0.05" />
        </geometry>
    </collision>
    <xacro:inertial_cylinder mass="0.1" length="0.05" radius="0.05">
        <origin xyz="0 0 0" rpy="0 0 0"/>
    </xacro:inertial_cylinder>
    </link>

    <!-- R RIGHT WHEEL -->

<joint name="R_right_wheel_joint" type="continuous">
    <parent link="base_link"/>
    <child link="R_right_wheel"/>
    <origin xyz="-0.1 -0.175 0.05" rpy="${pi/2} 0 0"/>
    <axis xyz="0 0 1"/>
</joint>

<link name="R_right_wheel">
    <visual>
        <geometry>
            <cylinder length="0.04" radius="0.05" />
        </geometry>
        <material name="blue"/>
    </visual>
    
    <collision>
        <geometry>
            <cylinder length="0.04" radius="0.05" />
        </geometry>
    </collision>
    <xacro:inertial_cylinder mass="10" length="0.05" radius="0.05">
        <origin xyz="0 0 0" rpy="0 0 0"/>
    </xacro:inertial_cylinder>
</link>
<gazebo reference="R_right_wheel">
    <material>Gazebo/Red</material>
</gazebo>

<!--R_ARM-->
<joint name="R_ARM_joint" type="revolute">
    <parent link="base_link"/>
    <child link="R_ARM"/>
    <origin xyz="0.25 -0.17 0.25" rpy="0 0 0"/>
    <axis xyz="0 1 0"/>
     <limit effort="2000.0" lower="0.0" upper="${2.191}" velocity="0.5"/>
     <dynamics damping="1" friction="0.6"/>
</joint>

<link name="R_ARM">
    <visual>
        <origin xyz="0 0 0.15" rpy="0 0 0"/>
        <geometry>
            <cylinder length="0.3" radius="0.01" />
        </geometry>
        <material name="red"/>
    </visual>
    <collision>
        <origin xyz="0 0 0.15" rpy="0 0 0"/>
        <geometry>
            <cylinder length="0.3" radius="0.01" />
        </geometry>
    </collision>
    <xacro:inertial_cylinder mass="0.01" length="0.3" radius="0.01">
        <origin xyz="0 0 0.15" rpy="0 0 0"/>
    </xacro:inertial_cylinder>
</link>

<gazebo reference="R_ARM">
    <material>Gazebo/Red</material>
</gazebo>



<!--L_ARM-->
<joint name="L_ARM_joint" type="fixed">
    <parent link="R_ARM"/>
    <child link="L_ARM"/>
    <origin xyz="0 0.33 0" rpy="0 0 0"/>
    <axis xyz="0 1 0"/>
</joint>

<link name="L_ARM">
    <visual>
        <origin xyz="0 0 0.15" rpy="0 0 0"/>
        <geometry>
            <cylinder length="0.3" radius="0.01" />
        </geometry>
        <material name="red"/>
    </visual>
    <collision>
        <origin xyz="0 0 0.15" rpy="0 0 0"/>
        <geometry>
            <cylinder length="0.3" radius="0.01" />
        </geometry>
    </collision>
    <xacro:inertial_cylinder mass="0.01" length="0.3" radius="0.01">
        <origin xyz="0 0 0.15" rpy="0 0 0"/>
    </xacro:inertial_cylinder>
</link>

<gazebo reference="L_ARM">
    <material>Gazebo/Red</material>
</gazebo>


<!-- bucket_joint -->
<joint name="bucket_joint" type="revolute">
    <parent link="R_ARM"/>
    <child link="bucket"/>
    <origin xyz="0 0.16 0.3" rpy="0 0 ${pi/2}"/>
    <axis xyz="-1 0 0"/>
     <limit effort="1000.0" lower="2.174" upper="3.14" velocity="0.5"/>
     <dynamics damping="1" friction="1"/>
</joint>


<link name="bucket">
<visual>
    <!-- <origin xyz="0.15 0 0.075" rpy="0 0 ${pi/2}"/> -->
    <geometry>
        <mesh filename="file://$(find articubot_one)/description/bucket.dae" scale="0.52 0.5 0.5"/>
    </geometry>
    <material name="white"/>
</visual>
<collision>
    <!-- <origin xyz="0.15 0 0.075" rpy="0 0 ${pi/2}"/> -->
    <geometry>/home/swg/robot_ws/src/articubot_one/model/Body1.dae
        <mesh filename="file://$(find articubot_one)/description/bucket.dae" scale="0.52 0.5 0.5"/>
    </geometry>
</collision>
<xacro:inertial_box mass="0.001" x="0.2" y="0.2" z="0.15">
    <origin xyz="0 0 0" rpy="0 0 0"/>
</xacro:inertial_box>
</link>

<gazebo reference="bucket">
    <material>Gazebo/White</material>
</gazebo>



<!-- hand_joint -->
<joint name="hand_joint" type="revolute">
    <parent link="bucket"/>
    <child link="hand"/>
    <origin xyz="-0.15 -0 0" rpy="0 0 ${pi/2}"/>
    <axis xyz="0 -1 0"/>
     <limit effort="1000.0" lower="1.257" upper="1.545" velocity="0.5"/>
     <dynamics damping="1" friction="0.01"/>
</joint>

<link name="hand">
    <visual>
        <origin xyz="0 0 0.3" rpy="0 0 0"/> 
        <geometry>
            <box size="0.01 0.01 0.4" />
        </geometry>
        <material name="red"/>
    </visual>
    <collision>
        <origin xyz="0 0 0.3" rpy="0 0 0"/>
        <geometry>
            <box size="0.01 0.01 0.4" />
        </geometry>
    </collision>
    <xacro:inertial_box mass="0.001" x="0.01" y="0.01" z="0.4  ">
        <origin xyz="0 0 0.3" rpy="0 0 0"/>
    </xacro:inertial_box>
</link>
<gazebo reference="hand">
    <material>Gazebo/White</material>
</gazebo>



<joint name="pris_joint" type="prismatic">
    <parent link="hand"/>
    <child link="pris"/>
    <origin xyz="0 0 0.3" rpy="0 ${pi/2} ${pi/2}"/>
    <axis xyz="1 0 0"/>
     <limit effort="1000.0" lower="0.0" upper="0.295" velocity="0.3"/>
     <dynamics damping="1" friction="0.11"/>
</joint>

<link name="pris">
    <visual>
        <origin xyz="-0.2 0 -0.2" rpy="0 0 0"/> 
        <geometry>
            <box size="0.01 0.2 0.4" />
        </geometry>
        <material name="red"/>
    </visual>
    <collision>
        <origin xyz="-0.2 0 -0.2" rpy="0 0 0"/>
        <geometry>
            <box size="0.01 0.01 0.4" />
        </geometry>
    </collision>
    <xacro:inertial_box mass="0.001" x="0.01" y="0.02" z="0.4  ">
        <origin xyz="-0 0 -0" rpy="0 0 0"/>
    </xacro:inertial_box>
    
</link>
<gazebo reference="pris">
    <material>Gazebo/White</material>
</gazebo>
<!-- CASTER WHEEL 

<joint name="caster_wheel_joint" type="fixed">
    <parent link="chassis"/>
    <child link="caster_wheel"/>
    <origin xyz="0.24 0 0" rpy="0 0 0"/>
</joint>

<link name="caster_wheel">
    <visual>
        <geometry>
            <sphere radius="0.05" />
        </geometry>
        <material name="black"/>
    </visual>
    <collision>
        <geometry>
            <sphere radius="0.05" />
        </geometry>
    </collision>
    <xacro:inertial_sphere mass="0.1" radius="0.05">
        <origin xyz="0 0 0" rpy="0 0 0"/>
    </xacro:inertial_sphere>
</link>
-->
<gazebo reference="left_wheel">
    
    <mu1 value="0.5"/>
    <mu2 value="0.8"/>
</gazebo>

<gazebo reference="right_wheel">
    
    <mu1 value="0.5"/>
    <mu2 value="0.8"/>
</gazebo>

<gazebo reference="R_left_wheel">
    
    <mu1 value="0.5"/>
    <mu2 value="0.8"/>
</gazebo>
<gazebo reference="R_right_wheel">
    <mu1 value="0.5"/>
    <mu2 value="0.8"/>
</gazebo>



</robot>